Workbook
Name demo: #REF!
Name demo: #REF!
Name wenjian: #REF!
Name wenjian: #REF!
Name 教师总课程表: #REF!
Name 教师总课程表: #REF!
Name 未设置课程表: #REF!
Name 未设置课程表: #REF!
Name 总课程表: #REF!
Name 总课程表: #REF!

Sheet 总课表
A1: 2020-2021学年18、19、20级第二学期总课表（下埠教学点） （第1节 8:10-8:55 第2节 9:05-9:50 第3节 映荷楼（10:05-10:50） 践行楼（10:20-11:05） 第4节 映荷楼（11:00-11:45） 践行楼（11:15-12:00 ） 第5节 14:10-14:55 第6节 15:05-15:50 晚自习 19:00-20:30）
A2: 班级 节次及时间 | B2: 一1∽2 | C2: 一3∽4 | D2: 一5∽6 | E2: 一晚自习 | F2: 二1∽2 | G2: 二3∽4 | H2: 二5∽6 | I2: 二晚自习 | J2: 三1∽2 | K2: 三3∽4 | L2: 三5∽6 | M2: 三晚自习 | N2: 四1∽2 | O2: 四3∽4 | P2: 四5∽6 | Q2: 四晚自习 | R2: 五1∽2 | S2: 五3∽4 | T2: 五5∽6 | U2: 五晚自习 | V2: 班会教室
A3: 18计应1 | B3: 软件工程 李星 践行楼401 | C3: Java项目综合案例开发 王昌原 践行楼401 | E3: 耿锐 报告厅 | F3: 毕业设计 践行楼203 | G3: Java项目综合案例开发 王昌原 践行楼403 | I3: 耿锐 报告厅 | J3: Java项目综合案例开发 王昌原 践行楼401 | K3: Web项目综合案例开发 耿锐 践行楼401 | L3: 毕业设计 践行楼101 | M3: 耿锐 报告厅 | N3: Web项目综合案例开发 耿锐 践行楼401 | O3: 就业指导 赵艳云 践行楼401 | P3: 毕业设计 践行楼401 | Q3: 赵艳云 报告厅 | R3: Web项目综合案例开发 耿锐 践行楼101 | V3: 践行楼401
A4: 18计应2 | B4: 软件工程 李星 践行楼401 | C4: Web项目综合案例开发 耿锐 践行楼403 | E4: 耿锐 报告厅 | F4: 毕业设计 践行楼203 | G4: Web项目综合案例开发 耿锐 践行楼204 | I4: 耿锐 报告厅 | J4: Web项目综合案例开发 耿锐 践行楼403 | K4: Java项目综合案例开发 王昌原 践行楼403 | L4: 毕业设计 践行楼101 | M4: 耿锐 报告厅 | O4: Java项目综合案例开发 王昌原 践行楼201 | P4: 毕业设计 践行楼401 | Q4: 赵艳云 报告厅 | R4: 就业指导 赵艳云 践行楼401 | S4: Java项目综合案例开发 王昌原 践行楼401 | V4: 践行楼401
A5: 18计应3 | B5: Java项目综合案例开发 王昌原 践行楼403 | D5: Web项目综合案例开发 耿锐 践行楼401 | E5: 耿锐 报告厅 | F5: Java项目综合案例开发 王昌原 践行楼401 | G5: 软件工程 李星 践行楼401 | I5: 耿锐 报告厅 | J5: 毕业设计 践行楼102 | K5: 毕业设计 践行楼102 | L5: Java项目综合案例开发 王昌原 践行楼401 | M5: 耿锐 报告厅 | N5: 就业指导 赵艳云 践行楼403 | O5: Web项目综合案例开发 耿锐 践行楼403 | Q5: 赵艳云 报告厅 | R5: 毕业设计 映荷楼201 | S5: Web项目综合案例开发 耿锐 映荷楼201 | V5: 践行楼403
A6: 18计应4 | B6: Web项目综合案例开发 耿锐 践行楼204 | D6: Java项目综合案例开发 王昌原 践行楼403 | E6: 耿锐 报告厅 | F6: Web项目综合案例开发 耿锐 践行楼403 | G6: 软件工程 李星 践行楼401 | I6: 耿锐 报告厅 | J6: 毕业设计 践行楼102 | K6: 毕业设计 践行楼102 | L6: Web项目综合案例开发 耿锐 践行楼403 | M6: 耿锐 报告厅 | N6: Java项目综合案例开发 王昌原 践行楼202 | O6: 毕业设计 践行楼104 | Q6: 赵艳云 报告厅 | R6: Java项目综合案例开发 王昌原 践行楼403 | S6: 就业指导 赵艳云 践行楼403 | V6: 践行楼403
A7: 18市销1 | B7: 新媒体营销 袁超 映荷楼103 | D7: 办公软件高级应用 唐晗 映荷楼302 | E7: 袁军萍 践行楼401 | F7: 就业指导 赵艳云 映荷楼201 | G7: 新媒体营销 袁超 映荷楼103 | H7: 零售业营销 徐艳 映荷楼201 | I7: 袁军萍 践行楼401 | J7: 交际与口才 钟丽娜 践行楼201 | K7: 零售业营销 徐艳 映荷楼201 | L7: 办公软件高级应用 唐晗 ★机房301 | M7: 赵艳云 践行楼401 | N7: 交际与口才 钟丽娜 践行楼103 | O7: 零售业营销 徐艳 映荷楼201 | Q7: 袁超 践行楼401 | R7: 新媒体营销 袁超 映荷楼103 | S7: 办公软件高级应用 唐晗 映荷楼302 | V7: 报告厅
A8: 18市销2 | B8: 办公软件高级应用 袁军萍 映荷楼201 | C8: 零售业营销 徐艳 映荷楼204 | D8: 新媒体营销 袁超 映荷楼104 | E8: 袁军萍 践行楼401 | F8: 办公软件高级应用 袁军萍 ★机房301 | G8: 零售业营销 徐艳 映荷楼203 | I8: 袁军萍 践行楼401 | J8: 交际与口才 钟丽娜 践行楼201 | K8: 就业指导 赵艳云 映荷楼403 | L8: 零售业营销 徐艳 映荷楼103 | M8: 赵艳云 践行楼401 | N8: 交际与口才 钟丽娜 践行楼103 | O8: 新媒体营销 袁超 映荷楼101 | P8: 办公软件高级应用 袁军萍 映荷楼202 | Q8: 袁超 践行楼401 | S8: 新媒体营销 袁超 映荷楼202 | V8: 报告厅
A9: 19物网1 | B9: QT界面编程 王建立 践行楼101 | C9: 无线传感技术 李俊杰 践行楼101 | D9: 数据库技术基础 李星 映荷楼403 | E9: 李星 践行楼101 | F9: QT界面编程 王建立 ★机房402 | G9: ARM体系结构与驱动开发 邹浩桢 践行楼101 | H9: 创新与创业 刘明良 报告厅 | I9: 钟丽娜 践行楼204 | J9: 数据库技术基础 李星 ★机房301 | K9: ARM体系结构与驱动开发 邹浩桢 ★机房302 | L9: 无线传感技术 李俊杰 ★机房302 | M9: 徐行 践行楼204 | N9: 数据库技术基础 李星 践行楼101 | O9: ARM体系结构与驱动开发 邹浩桢 践行楼101 | P9: Java程序设计 徐行 践行楼102 | Q9: 徐行 践行楼101 | S9: Java程序设计 徐行 ★机房404 | V9: 践行楼101
A10: 19物网2 | B10: 数据库技术基础 张磊 ★机房302 | C10: QT界面编程 王建立 践行楼102 | D10: 无线传感技术 李俊杰 践行楼102 | E10: 张磊 践行楼102 | F10: 数据库技术基础 张磊 践行楼102 | G10: QT界面编程 王建立 ★机房402 | H10: 创新与创业 刘明良 报告厅 | I10: 钟丽娜 践行楼204 | J10: 数据库技术基础 张磊 映荷楼202 | K10: Java程序设计 徐行 ★机房303 | L10: ARM体系结构与驱动开发 邹浩桢 践行楼102 | M10: 徐行 践行楼204 | O10: 无线传感技术 李俊杰 ★机房303 | P10: ARM体系结构与驱动开发 邹浩桢 ★机房303 | Q10: 钟丽娜 践行楼102 | R10: Java程序设计 徐行 践行楼102 | S10: ARM体系结构与驱动开发 邹浩桢 践行楼102 | V10: 践行楼102
A11: 19物网3 | B11: ARM体系结构与驱动开发 邹浩桢 践行楼103 | C11: 数据库技术基础 张磊 ★机房302 | D11: QT界面编程 王建立 践行楼103 | E11: QT界面编程 王建立 ★机房302 | F11: ARM体系结构与驱动开发 邹浩桢 ★机房404 | G11: 数据库技术基础 张磊 践行楼103 | H11: 创新与创业 刘明良 报告厅 | I11: 无线传感技术 邹浩桢 践行楼103 | L11: Java程序设计 徐春华 践行楼103 | M11: 张磊 践行楼103 | O11: 数据库技术基础 张磊 践行楼103 | Q11: 无线传感技术 邹浩桢 ★机房301 | R11: ARM体系结构与驱动开发 邹浩桢 践行楼103 | S11: Java程序设计 徐春华 ★机房303 | V11: 践行楼103
A12: 19物网4 | B12: 数据库技术基础 徐行 践行楼104 | C12: 无线传感技术 邹浩桢 践行楼104 | D12: ARM体系结构与驱动开发 邹浩桢 践行楼104 | E12: 徐春华 践行楼104 | F12: Java程序设计 徐春华 践行楼104 | G12: 数据库技术基础 徐行 ★机房302 | H12: 创新与创业 刘明良 报告厅 | I12: 何丹 践行楼104 | J12: ARM体系结构与驱动开发 邹浩桢 ★机房303 | K12: Java程序设计 徐春华 ★机房402 | L12: 数据库技术基础 徐行 践行楼104 | M12: 无线传感技术 邹浩桢 ★机房301 | N12: ARM体系结构与驱动开发 邹浩桢 践行楼104 | Q12: 何丹 践行楼204 | R12: QT界面编程 王建立 ★机房402 | S12: QT界面编程 王建立 践行楼104 | V12: 践行楼104
A13: 19计网1 | B13: Shell脚本编程 李俊杰 映荷楼202 | C13: 云计算应用管理 陈良 践行楼201 | D13: Java程序设计 徐春华 践行楼201 | E13: Shell脚本编程 李俊杰 ★机房301 | F13: 云计算高级运维 陈良 践行楼201 | G13: 创新与创业 刘明良 报告厅 | I13: 黎海春 映荷楼302 | J13: Java程序设计 徐春华 ★机房402 | K13: WEB前端开发 李星 践行楼201 | L13: 云计算应用管理 陈良 ★机房303 | M13: 徐春华 践行楼201 | N13: Shell脚本编程 李俊杰 践行楼201 | O13: 云计算高级运维 陈良 ★机房402 | P13: WEB前端开发 李星 ★机房301 | Q13: 李星 践行楼201 | S13: Shell脚本编程 李俊杰 ★机房402 | V13: 践行楼201
A14: 19计网2 | B14: 云计算应用管理 陈良 映荷楼203 | D14: 云计算高级运维 陈良 践行楼202 | E14: 黎海春 践行楼202 | F14: Shell脚本编程 李俊杰 践行楼202 | G14: 创新与创业 刘明良 报告厅 | H14: Shell脚本编程 李俊杰 ★机房301 | I14: 徐春华 践行楼202 | J14: 云计算应用管理 陈良 ★机房404 | K14: Shell脚本编程 李俊杰 践行楼202 | L14: WEB前端开发 李星 践行楼202 | M14: 李星 践行楼202 | N14: Java程序设计 徐春华 映荷楼202 | P14: Java程序设计 徐春华 ★机房402 | Q14: Shell脚本编程 李俊杰 ★机房302 | R14: WEB前端开发 李星 ★机房301 | S14: 云计算高级运维 陈良 ★机房302 | V14: 践行楼202
A15: 19计网3 | C15: Java程序设计 徐行 践行楼203 | D15: Java程序设计 徐行 ★机房301 | E15: 徐行 践行楼203 | G15: 创新与创业 刘明良 报告厅 | H15: 云计算应用管理 陈良 践行楼203 | I15: 云计算高级运维 陈良 践行楼203 | J15: Shell脚本编程 李俊杰 践行楼203 | M15: Shell脚本编程 李俊杰 ★机房302 | N15: 云计算应用管理 陈良 ★机房404 | O15: WEB前端开发 李星 践行楼102 | P15: Shell脚本编程 李俊杰 践行楼202 | Q15: 云计算高级运维 陈良 ★机房303 | R15: Shell脚本编程 李俊杰 ★机房404 | S15: WEB前端开发 李星 ★机房301 | V15: 践行楼203
A16: 19市销 | C16: 推销技巧 袁超 践行楼204 | D16: 广告策划与创意 徐艳 践行楼204 | E16: 袁超 践行楼204 | F16: 推销技巧 袁超 践行楼204 | G16: 创新与创业 刘明良 报告厅 | H16: 营销型网站建设 王昌原 践行楼204 | I16: 袁超 践行楼101 | J16: 推销技巧 袁超 践行楼204 | M16: 搜索引擎优化 陈良 ★机房303 | N16: 经济法 陈冉 践行楼204 | O16: 经济法 陈冉 践行楼204 | P16: 广告策划与创意 徐艳 践行楼204 | Q16: 营销型网站建设 王昌原 ★机房402 | R16: 搜索引擎优化 陈良 践行楼204 | S16: 广告策划与创意 徐艳 践行楼204 | V16: 践行楼204
A17: 20幼教1 | B17: 语文2 贺春 践行楼201 | C17: 政治2 胡玲 映荷楼103 | D17: 英语2 彭润华 映荷楼103 | E17: 彭润华 映荷楼103 | F17: 政治2 胡玲 映荷楼103 | G17: 语文2 贺春 践行楼202 | H17: 计算机应用基础2 唐晗 映荷楼103 | I17: 唐晗 映荷楼103 | J17: 幼儿绘画训练2 吴俊杰 映荷楼103 | K17: 形体训练2 曾婧玉 映荷楼405 | L17: 钢琴基础与视唱练耳2 朱朋 映荷楼102 | M17: 王丽 映荷楼103 | N17: 英语2 彭润华 映荷楼103 | O17: 体育2 柳金堤 | P17: 数学2 王丽 践行楼201 | Q17: 贺春 践行楼202 | R17: 计算机应用基础2 唐晗 ★机房303 | S17: 数学2 王丽 践行楼202 | V17: 映荷楼103
A18: 20幼教2 | B18: 语文2 贺春 践行楼201 | C18: 计算机应用基础2 唐晗 映荷楼202 | D18: 政治2 胡玲 映荷楼202 | E18: 彭润华 映荷楼202 | F18: 英语2 刘敏 映荷楼202 | G18: 语文2 贺春 践行楼202 | H18: 政治2 胡玲 映荷楼202 | I18: 贺春 映荷楼202 | J18: 钢琴基础与视唱练耳2 朱朋 映荷楼102 | K18: 幼儿绘画训练2 吴俊杰 映荷楼202 | L18: 形体训练2 曾婧玉 映荷楼405 | M18: 胡玲 映荷楼202 | N18: 体育2 宋剑文 | O18: 计算机应用基础2 唐晗 ★机房404 | P18: 数学2 王丽 践行楼201 | Q18: 贺春 践行楼202 | R18: 英语2 刘敏 映荷楼202 | S18: 数学2 王丽 践行楼202 | V18: 映荷楼202
A19: 20幼教3 | B19: 数学2 游思明 践行楼202 | C19: 英语2 陈娟 映荷楼201 | D19: 计算机应用基础2 黄仕尘 映荷楼201 | E19: 陈娟 映荷楼201 | F19: 数学2 游思明 践行楼101 | G19: 政治2 胡玲 映荷楼201 | H19: 体育2 彭明 | I19: 胡玲 映荷楼201 | J19: 形体训练2 曾婧玉 映荷楼405 | K19: 钢琴基础与视唱练耳2 朱朋 映荷楼102 | L19: 幼儿绘画训练2 吴俊杰 映荷楼201 | M19: 唐晗 映荷楼201 | N19: 英语2 陈娟 映荷楼201 | O19: 语文2 贺春 践行楼203 | P19: 政治2 胡玲 映荷楼201 | Q19: 胡玲 映荷楼202 | R19: 语文2 贺春 践行楼201 | S19: 计算机应用基础2 黄仕尘 ★机房304 | V19: 映荷楼201
A20: 20计应1 | B20: 语文2 周香萍 践行楼203 | C20: 数学2 游思明 践行楼202 | D20: 政治2 吴友才 映荷楼203 | E20: 吴友才 映荷楼203 | F20: 语文2 周香萍 践行楼103 | G20: 数学2 游思明 践行楼201 | I20: 周香萍 践行楼201 | J20: VB程序设计基础 袁军萍 映荷楼203 | K20: 计算机应用基础2 李含笑 映荷楼203 | L20: 政治2 吴友才 映荷楼203 | M20: 袁军萍 映荷楼203 | N20: VB程序设计基础 袁军萍 ★机房301 | O20: 英语2 谢鹏 映荷楼203 | P20: 计算机应用基础2 李含笑 ★机房302 | Q20: 李含笑 映荷楼203 | R20: 体育2 彭明 | S20: 英语2 谢鹏 映荷楼203 | V20: 映荷楼203
A21: 20计应2 | B21: 语文2 周香萍 践行楼203 | C21: 数学2 游思明 践行楼202 | D21: 英语2 谢鹏 映荷楼404 | E21: 周香萍 映荷楼403 | F21: 语文2 周香萍 践行楼103 | G21: 数学2 游思明 践行楼201 | I21: 周香萍 践行楼201 | J21: 计算机应用基础2 李含笑 映荷楼403 | K21: 政治2 吴友才 映荷楼302 | L21: VB程序设计基础 袁军萍 映荷楼403 | M21: 李含笑 映荷楼403 | N21: 计算机应用基础2 李含笑 ★机房303 | O21: 政治2 吴友才 映荷楼202 | P21: 英语2 谢鹏 映荷楼302 | Q21: 谢鹏 映荷楼302 | R21: VB程序设计基础 袁军萍 ★机房302 | S21: 体育2 彭明 | V21: 映荷楼404
A22: 20电商1 | B22: 英语2 刘敏 映荷楼403 | C22: 应用文写作 柳航 映荷楼403 | D22: 语文2 贺春 践行楼101 | E22: 柳航 映荷楼304 | F22: FFICE办公自动化之Word 唐晗 映荷楼403 | G22: 英语2 刘敏 映荷楼403 | H22: 政治2 谢嘉祺 映荷楼104 | I22: 柳航 践行楼403 | J22: 数学2 王丽 践行楼101 | K22: FFICE办公自动化之Word 唐晗 ★机房301 | L22: 语文2 贺春 践行楼201 | M22: 贺春 映荷楼304 | N22: 体育2 柳金堤 | P22: 政治2 谢嘉祺 映荷楼103 | Q22: 谢嘉祺 映荷楼304 | R22: 数学2 王丽 践行楼202 | S22: 应用文写作 柳航 映荷楼103 | V22: 映荷楼304
A23: 20电商2 | B23: FFICE办公自动化之Word 唐晗 映荷楼302 | C23: 政治2 谢嘉祺 映荷楼302 | D23: 语文2 贺春 践行楼101 | E23: 唐晗 映荷楼303 | F23: 应用文写作 柳航 映荷楼302 | G23: 应用文写作 柳航 映荷楼302 | I23: 柳航 践行楼403 | J23: 数学2 王丽 践行楼101 | K23: 英语2 刘敏 映荷楼103 | L23: 语文2 贺春 践行楼201 | M23: 谢嘉祺 映荷楼303 | N23: FFICE办公自动化之Word 唐晗 ★机房304 | O23: 政治2 谢嘉祺 映荷楼104 | P23: 体育2 柳金堤 | Q23: 肖继林 映荷楼303 | R23: 数学2 王丽 践行楼202 | S23: 英语2 刘敏 映荷楼403 | V23: 映荷楼303
A24: 20计网 | B24: 计算机应用基础2 李含笑 映荷楼101 | C24: 政治2 吴友才 映荷楼203 | D24: 数学2 游思明 践行楼203 | E24: 谢鹏 映荷楼302 | F24: 计算机应用基础2 李含笑 ★机房303 | G24: 英语2 谢鹏 映荷楼402 | I24: 李含笑 映荷楼301 | J24: 数学2 游思明 践行楼202 | K24: C程序设计 张磊 映荷楼104 | L24: 英语2 谢鹏 映荷楼302 | M24: 吴友才 映荷楼302 | N24: C程序设计 张磊 ★机房302 | O24: 语文2 贺春 践行楼203 | P24: 体育2 彭明 | Q24: 张磊 映荷楼201 | R24: 语文2 贺春 践行楼201 | S24: 政治2 吴友才 映荷楼104 | V24: 映荷楼301
A25: 20会计 | B25: 数学2 游思明 践行楼202 | C25: 语文2 周香萍 映荷楼101 | D25: 演讲与口才 钟丽娜 映荷楼101 | E25: 文林一村 映荷楼101 | F25: 数学2 游思明 践行楼101 | G25: 英语2 陈娟 映荷楼101 | I25: 陈娟 映荷楼101 | J25: 语文2 周香萍 映荷楼101 | K25: Office办公自动化 袁军萍 映荷楼101 | L25: 体育2 彭明 | M25: 彭明 映荷楼101 | N25: 政治2 谢嘉祺 映荷楼101 | O25: Office办公自动化 袁军萍 ★机房301 | P25: 语文2 周香萍 映荷楼101 | Q25: 文林一村 映荷楼101 | R25: 政治2 谢嘉祺 映荷楼101 | S25: 英语2 陈娟 映荷楼101 | V25: 映荷楼101
A26: 20建工 | B26: 英语2 彭润华 映荷楼204 | C26: 体育2 彭明 | D26: 计算机应用基础2 袁军萍 映荷楼204 | E26: 彭明 映荷楼204 | F26: 英语2 彭润华 映荷楼204 | G26: 计算机应用基础2 袁军萍 ★机房301 | I26: 黄仕尘 映荷楼204 | J26: 工程制图基础 黄仕尘 映荷楼204 | K26: 数学2 王丽 践行楼101 | L26: 工程制图基础 黄仕尘 映荷楼101 | M26: 彭润华 映荷楼204 | N26: 语文2 周香萍 践行楼203 | O26: 数学2 王丽 践行楼202 | P26: 政治2 罗夏芸 映荷楼204 | Q26: 罗夏芸 映荷楼204 | R26: 政治2 罗夏芸 映荷楼104 | S26: 语文2 周香萍 践行楼203 | V26: 映荷楼204
A27: 20工造 | B27: 计算机应用基础2 黄仕尘 映荷楼104 | C27: AutoCAD 黄仕尘 映荷楼104 | D27: 体育2 彭明 | E27: 黄仕尘 映荷楼104 | F27: 计算机应用基础2 黄仕尘 ★机房302 | G27: 英语2 彭润华 映荷楼104 | I27: 彭润华 映荷楼104 | J27: 政治2 罗夏芸 映荷楼104 | K27: 数学2 王丽 践行楼101 | L27: 政治2 罗夏芸 映荷楼104 | M27: 周香萍 映荷楼104 | N27: 语文2 周香萍 践行楼203 | O27: 数学2 王丽 践行楼202 | P27: 英语2 彭润华 映荷楼104 | Q27: 王丽 映荷楼104 | R27: AutoCAD 黄仕尘 ★机房304 | S27: 语文2 周香萍 践行楼203 | V27: 映荷楼104
A28: 20机电 | B28: 政治2 罗夏芸 映荷楼402 | C28: 英语2 刘敏 映荷楼402 | D28: 英语2 刘敏 映荷楼402 | E28: 钟子良 践行楼201 | F28: 政治2 罗夏芸 映荷楼402 | G28: 语文2 周香萍 践行楼203 | I28: 罗夏芸 映荷楼402 | J28: 机械制图2 钟子良 映荷楼402 | K28: 机械制图2 钟子良 映荷楼402 | L28: 电工基础 钟子良 映荷楼402 | M28: 罗夏芸 践行楼203 | N28: 数学2 游思明 映荷楼402 | O28: 体育2 宋剑文 | P28: 数学2 游思明 映荷楼402 | Q28: 周香萍 映荷楼402 | R28: 语文2 周香萍 践行楼203 | S28: 电工基础 钟子良 映荷楼402 | V28: 映荷楼402
A29: 20机器人 | B29: 计算机应用基础2 钟子良 映荷楼404 | C29: 机械制图2 钟子良 映荷楼404 | D29: 数学2 游思明 践行楼203 | E29: 钟子良 践行楼201 | F29: 计算机应用基础2 钟子良 ★机房304 | G29: 语文2 周香萍 践行楼203 | I29: 罗夏芸 映荷楼403 | J29: 数学2 游思明 践行楼202 | K29: 政治2 罗夏芸 映荷楼404 | L29: 英语2 彭润华 映荷楼404 | M29: 罗夏芸 践行楼203 | N29: 政治2 罗夏芸 映荷楼404 | O29: 机械制图2 钟子良 映荷楼404 | P29: 体育2 宋剑文 | Q29: 钟子良 映荷楼403 | R29: 语文2 周香萍 践行楼203 | S29: 英语2 彭润华 映荷楼404 | V29: 映荷楼403
A30: 空余 教室 机房 | B30: 报告厅 践行楼 102 机房：301 303 304 402 404 | C30: 报告厅 践行楼 103 机房：301 303 304 402 404 | D30: 映荷楼 报告厅 机房302 303 304 402 404 | E30: 映荷楼 301 103 402 404 践行楼：103 403 机房303 304 402 404 | F30: 映荷楼101 104 203 404 报告厅 践行楼： | G30: 映荷楼202 204 404 践行楼：102 104 机房303 304 404 | H30: 映荷楼101 203 204 302 402 403 404 践行楼：101 102 103 104 201 202 401 403 机房302 303 304 402 404 | I30: 映荷楼 203 303 304 践行楼：102 机房301 302 303 304 402 404 | J30: 映荷楼 201 302 404 报告厅 践行楼：101 103 104 机房304 302 | K30: 映荷楼 204 报告厅 践行楼：103 203 204 机房304 404 | L30: 映荷楼 202 204 报告厅 践行楼：203 204 机房304 404 | M30: 映荷楼 301 402 404 践行楼：101 102 104 203 204 404 机房304 402 404 | N30: 映荷楼 104 203 204 204 302 403 报告厅 践行楼：202 | O30: 映荷楼 103 204 402 403 报告厅 践行楼： 机房304 302 | P30: 映荷楼 203 403 404 报告厅 践行楼：101 103 104 203 403 机房404 304 | Q30: 映荷楼 103 301 103 404 践行楼：104 103 203 404 204 机房304 404 | R30: 映荷楼 203 204 302 402 403 404 报告厅 践行楼：104 | S30: 映荷楼 204 报告厅 践行楼：101 103 201
B31: 映荷楼301、303、304白天做为18级创业实践使用，不能占用。

Sheet 单班课表
A1: 2020-2021第二学期单班课表
A2: 班级 | B2: 20计应2 | D2: 班会教室： | E2: =VLOOKUP($B$2,总课表!A:V,22,0) -> 映荷楼404
A3: 节次 | B3: 1--2 | C3: 3--4 | D3: 5--6 | E3: 晚自习
A4: 周一 | B4: =VLOOKUP($B$2,总课表!$A$3:$V$29,2,0) -> 语文2 周香萍 践行楼203 | C4: =VLOOKUP($B$2,总课表!$A$3:$V$29,3,0) -> 数学2 游思明 践行楼202 | D4: =VLOOKUP($B$2,总课表!$A$3:$V$29,4,0) -> 英语2 谢鹏 映荷楼404 | E4: =VLOOKUP($B$2,总课表!$A$3:$V$29,5,0) -> 周香萍 映荷楼403
A5: 周二 | B5: =VLOOKUP($B$2,总课表!$A$3:$V$29,6,0) -> 语文2 周香萍 践行楼103 | C5: =VLOOKUP($B$2,总课表!$A$3:$V$29,7,0) -> 数学2 游思明 践行楼201 | D5: =VLOOKUP($B$2,总课表!$A$3:$V$29,8,0) -> 0 | E5: =VLOOKUP($B$2,总课表!$A$3:$V$29,9,0) -> 周香萍 践行楼201
A6: 周三 | B6: =VLOOKUP($B$2,总课表!$A$3:$V$29,10,0) -> 计算机应用基础2 李含笑 映荷楼403 | C6: =VLOOKUP($B$2,总课表!$A$3:$V$29,11,0) -> 政治2 吴友才 映荷楼302 | D6: =VLOOKUP($B$2,总课表!$A$3:$V$29,12,0) -> VB程序设计基础 袁军萍 映荷楼403 | E6: =VLOOKUP($B$2,总课表!$A$3:$V$29,13,0) -> 李含笑 映荷楼403
A7: 周四 | B7: =VLOOKUP($B$2,总课表!$A$3:$V$29,14,0) -> 计算机应用基础2 李含笑 ★机房303 | C7: =VLOOKUP($B$2,总课表!$A$3:$V$29,15,0) -> 政治2 吴友才 映荷楼202 | D7: =VLOOKUP($B$2,总课表!$A$3:$V$29,16,0) -> 英语2 谢鹏 映荷楼302 | E7: =VLOOKUP($B$2,总课表!$A$3:$V$29,17,0) -> 谢鹏 映荷楼302
A8: 周五 | B8: =VLOOKUP($B$2,总课表!$A$3:$V$29,18,0) -> VB程序设计基础 袁军萍 ★机房302 | C8: =VLOOKUP($B$2,总课表!$A$3:$V$29,19,0) -> 体育2 彭明 | D8: =VLOOKUP($B$2,总课表!$A$3:$V$29,20,0) -> 0 | E8: =VLOOKUP($B$2,总课表!$A$3:$V$29,21,0) -> 0
A9: 每节课起止时间（课间休息10分钟）： 第1节 08:10-08:55 第2节 09:05-09:50 第3节 映荷楼（10:05-10:50） 践行楼（10:20-11:05） 第4节 映荷楼（11:00-11:45） 践行楼（11:15-12:00 ） 第5节 14:10-14:55 第6节 15:05-15:50 晚自习 19:00-20:30

Sheet 教师个人课程表
D1: 教师选择： | E1: 李星
A2: 班级 节次及时间 | B2: 一1∽2 | C2: 一3∽4 | D2: 一5∽6 | E2: 一晚自习 | F2: 二1∽2 | G2: 二3∽4 | H2: 二5∽6 | I2: 二晚自习 | J2: 三1∽2 | K2: 三3∽4 | L2: 三5∽6 | M2: 三晚自习 | N2: 四1∽2 | O2: 四3∽4 | P2: 四5∽6 | Q2: 四晚自习 | R2: 五1∽2 | S2: 五3∽4 | T2: 五5∽6 | U2: 五晚自习
A3: 18计应1 | B3: =IF(ISERROR(IF(FIND($E$1,总课表!B3)>1,总课表!B3,"")),"",IF(FIND($E$1,总课表!B3)>0,总课表!B3,"")) -> 软件工程 李星 践行楼401 | C3: =IF(ISERROR(IF(FIND($E$1,总课表!C3)>1,总课表!C3,"")),"",IF(FIND($E$1,总课表!C3)>0,总课表!C3,"")) | D3: =IF(ISERROR(IF(FIND($E$1,总课表!D3)>1,总课表!D3,"")),"",IF(FIND($E$1,总课表!D3)>0,总课表!D3,"")) | E3: =IF(ISERROR(IF(FIND($E$1,总课表!E3)>1,总课表!E3,"")),"",IF(FIND($E$1,总课表!E3)>0,总课表!E3,"")) | F3: =IF(ISERROR(IF(FIND($E$1,总课表!F3)>1,总课表!F3,"")),"",IF(FIND($E$1,总课表!F3)>0,总课表!F3,"")) | G3: =IF(ISERROR(IF(FIND($E$1,总课表!G3)>1,总课表!G3,"")),"",IF(FIND($E$1,总课表!G3)>0,总课表!G3,"")) | H3: =IF(ISERROR(IF(FIND($E$1,总课表!H3)>1,总课表!H3,"")),"",IF(FIND($E$1,总课表!H3)>0,总课表!H3,"")) | I3: =IF(ISERROR(IF(FIND($E$1,总课表!I3)>1,总课表!I3,"")),"",IF(FIND($E$1,总课表!I3)>0,总课表!I3,"")) | ... U3: =IF(ISERROR(IF(FIND($E$1,总课表!U3)>1,总课表!U3,"")),"",IF(FIND($E$1,总课表!U3)>0,总课表!U3,""))
A4: 18计应2 | B4: =IF(ISERROR(IF(FIND($E$1,总课表!B4)>1,总课表!B4,"")),"",IF(FIND($E$1,总课表!B4)>0,总课表!B4,"")) -> 软件工程 李星 践行楼401 | C4: =IF(ISERROR(IF(FIND($E$1,总课表!C4)>1,总课表!C4,"")),"",IF(FIND($E$1,总课表!C4)>0,总课表!C4,"")) | D4: =IF(ISERROR(IF(FIND($E$1,总课表!D4)>1,总课表!D4,"")),"",IF(FIND($E$1,总课表!D4)>0,总课表!D4,"")) | E4: =IF(ISERROR(IF(FIND($E$1,总课表!E4)>1,总课表!E4,"")),"",IF(FIND($E$1,总课表!E4)>0,总课表!E4,"")) | F4: =IF(ISERROR(IF(FIND($E$1,总课表!F4)>1,总课表!F4,"")),"",IF(FIND($E$1,总课表!F4)>0,总课表!F4,"")) | G4: =IF(ISERROR(IF(FIND($E$1,总课表!G4)>1,总课表!G4,"")),"",IF(FIND($E$1,总课表!G4)>0,总课表!G4,"")) | H4: =IF(ISERROR(IF(FIND($E$1,总课表!H4)>1,总课表!H4,"")),"",IF(FIND($E$1,总课表!H4)>0,总课表!H4,"")) | I4: =IF(ISERROR(IF(FIND($E$1,总课表!I4)>1,总课表!I4,"")),"",IF(FIND($E$1,总课表!I4)>0,总课表!I4,"")) | ... U4: =IF(ISERROR(IF(FIND($E$1,总课表!U4)>1,总课表!U4,"")),"",IF(FIND($E$1,总课表!U4)>0,总课表!U4,""))
A5: 18计应3 | B5: =IF(ISERROR(IF(FIND($E$1,总课表!B5)>1,总课表!B5,"")),"",IF(FIND($E$1,总课表!B5)>0,总课表!B5,"")) | C5: =IF(ISERROR(IF(FIND($E$1,总课表!C5)>1,总课表!C5,"")),"",IF(FIND($E$1,总课表!C5)>0,总课表!C5,"")) | D5: =IF(ISERROR(IF(FIND($E$1,总课表!D5)>1,总课表!D5,"")),"",IF(FIND($E$1,总课表!D5)>0,总课表!D5,"")) | E5: =IF(ISERROR(IF(FIND($E$1,总课表!E5)>1,总课表!E5,"")),"",IF(FIND($E$1,总课表!E5)>0,总课表!E5,"")) | F5: =IF(ISERROR(IF(FIND($E$1,总课表!F5)>1,总课表!F5,"")),"",IF(FIND($E$1,总课表!F5)>0,总课表!F5,"")) | G5: =IF(ISERROR(IF(FIND($E$1,总课表!G5)>1,总课表!G5,"")),"",IF(FIND($E$1,总课表!G5)>0,总课表!G5,"")) -> 软件工程 李星 践行楼401 | H5: =IF(ISERROR(IF(FIND($E$1,总课表!H5)>1,总课表!H5,"")),"",IF(FIND($E$1,总课表!H5)>0,总课表!H5,"")) | I5: =IF(ISERROR(IF(FIND($E$1,总课表!I5)>1,总课表!I5,"")),"",IF(FIND($E$1,总课表!I5)>0,总课表!I5,"")) | ... U5: =IF(ISERROR(IF(FIND($E$1,总课表!U5)>1,总课表!U5,"")),"",IF(FIND($E$1,总课表!U5)>0,总课表!U5,""))
A6: 18计应4 | B6: =IF(ISERROR(IF(FIND($E$1,总课表!B6)>1,总课表!B6,"")),"",IF(FIND($E$1,总课表!B6)>0,总课表!B6,"")) | C6: =IF(ISERROR(IF(FIND($E$1,总课表!C6)>1,总课表!C6,"")),"",IF(FIND($E$1,总课表!C6)>0,总课表!C6,"")) | D6: =IF(ISERROR(IF(FIND($E$1,总课表!D6)>1,总课表!D6,"")),"",IF(FIND($E$1,总课表!D6)>0,总课表!D6,"")) | E6: =IF(ISERROR(IF(FIND($E$1,总课表!E6)>1,总课表!E6,"")),"",IF(FIND($E$1,总课表!E6)>0,总课表!E6,"")) | F6: =IF(ISERROR(IF(FIND($E$1,总课表!F6)>1,总课表!F6,"")),"",IF(FIND($E$1,总课表!F6)>0,总课表!F6,"")) | G6: =IF(ISERROR(IF(FIND($E$1,总课表!G6)>1,总课表!G6,"")),"",IF(FIND($E$1,总课表!G6)>0,总课表!G6,"")) -> 软件工程 李星 践行楼401 | H6: =IF(ISERROR(IF(FIND($E$1,总课表!H6)>1,总课表!H6,"")),"",IF(FIND($E$1,总课表!H6)>0,总课表!H6,"")) | I6: =IF(ISERROR(IF(FIND($E$1,总课表!I6)>1,总课表!I6,"")),"",IF(FIND($E$1,总课表!I6)>0,总课表!I6,"")) | ... U6: =IF(ISERROR(IF(FIND($E$1,总课表!U6)>1,总课表!U6,"")),"",IF(FIND($E$1,总课表!U6)>0,总课表!U6,""))
A7: 18市销1 | B7: =IF(ISERROR(IF(FIND($E$1,总课表!B7)>1,总课表!B7,"")),"",IF(FIND($E$1,总课表!B7)>0,总课表!B7,"")) | C7: =IF(ISERROR(IF(FIND($E$1,总课表!C7)>1,总课表!C7,"")),"",IF(FIND($E$1,总课表!C7)>0,总课表!C7,"")) | D7: =IF(ISERROR(IF(FIND($E$1,总课表!D7)>1,总课表!D7,"")),"",IF(FIND($E$1,总课表!D7)>0,总课表!D7,"")) | E7: =IF(ISERROR(IF(FIND($E$1,总课表!E7)>1,总课表!E7,"")),"",IF(FIND($E$1,总课表!E7)>0,总课表!E7,"")) | F7: =IF(ISERROR(IF(FIND($E$1,总课表!F7)>1,总课表!F7,"")),"",IF(FIND($E$1,总课表!F7)>0,总课表!F7,"")) | G7: =IF(ISERROR(IF(FIND($E$1,总课表!G7)>1,总课表!G7,"")),"",IF(FIND($E$1,总课表!G7)>0,总课表!G7,"")) | H7: =IF(ISERROR(IF(FIND($E$1,总课表!H7)>1,总课表!H7,"")),"",IF(FIND($E$1,总课表!H7)>0,总课表!H7,"")) | I7: =IF(ISERROR(IF(FIND($E$1,总课表!I7)>1,总课表!I7,"")),"",IF(FIND($E$1,总课表!I7)>0,总课表!I7,"")) | ... U7: =IF(ISERROR(IF(FIND($E$1,总课表!U7)>1,总课表!U7,"")),"",IF(FIND($E$1,总课表!U7)>0,总课表!U7,""))
A8: 18市销2 | B8: =IF(ISERROR(IF(FIND($E$1,总课表!B8)>1,总课表!B8,"")),"",IF(FIND($E$1,总课表!B8)>0,总课表!B8,"")) | C8: =IF(ISERROR(IF(FIND($E$1,总课表!C8)>1,总课表!C8,"")),"",IF(FIND($E$1,总课表!C8)>0,总课表!C8,"")) | D8: =IF(ISERROR(IF(FIND($E$1,总课表!D8)>1,总课表!D8,"")),"",IF(FIND($E$1,总课表!D8)>0,总课表!D8,"")) | E8: =IF(ISERROR(IF(FIND($E$1,总课表!E8)>1,总课表!E8,"")),"",IF(FIND($E$1,总课表!E8)>0,总课表!E8,"")) | F8: =IF(ISERROR(IF(FIND($E$1,总课表!F8)>1,总课表!F8,"")),"",IF(FIND($E$1,总课表!F8)>0,总课表!F8,"")) | G8: =IF(ISERROR(IF(FIND($E$1,总课表!G8)>1,总课表!G8,"")),"",IF(FIND($E$1,总课表!G8)>0,总课表!G8,"")) | H8: =IF(ISERROR(IF(FIND($E$1,总课表!H8)>1,总课表!H8,"")),"",IF(FIND($E$1,总课表!H8)>0,总课表!H8,"")) | I8: =IF(ISERROR(IF(FIND($E$1,总课表!I8)>1,总课表!I8,"")),"",IF(FIND($E$1,总课表!I8)>0,总课表!I8,"")) | ... U8: =IF(ISERROR(IF(FIND($E$1,总课表!U8)>1,总课表!U8,"")),"",IF(FIND($E$1,总课表!U8)>0,总课表!U8,""))
A9: 19物网1 | B9: =IF(ISERROR(IF(FIND($E$1,总课表!B9)>1,总课表!B9,"")),"",IF(FIND($E$1,总课表!B9)>0,总课表!B9,"")) | C9: =IF(ISERROR(IF(FIND($E$1,总课表!C9)>1,总课表!C9,"")),"",IF(FIND($E$1,总课表!C9)>0,总课表!C9,"")) | D9: =IF(ISERROR(IF(FIND($E$1,总课表!D9)>1,总课表!D9,"")),"",IF(FIND($E$1,总课表!D9)>0,总课表!D9,"")) -> 数据库技术基础 李星 映荷楼403 | E9: =IF(ISERROR(IF(FIND($E$1,总课表!E9)>1,总课表!E9,"")),"",IF(FIND($E$1,总课表!E9)>0,总课表!E9,"")) -> 李星 践行楼101 | F9: =IF(ISERROR(IF(FIND($E$1,总课表!F9)>1,总课表!F9,"")),"",IF(FIND($E$1,总课表!F9)>0,总课表!F9,"")) | G9: =IF(ISERROR(IF(FIND($E$1,总课表!G9)>1,总课表!G9,"")),"",IF(FIND($E$1,总课表!G9)>0,总课表!G9,"")) | H9: =IF(ISERROR(IF(FIND($E$1,总课表!H9)>1,总课表!H9,"")),"",IF(FIND($E$1,总课表!H9)>0,总课表!H9,"")) | I9: =IF(ISERROR(IF(FIND($E$1,总课表!I9)>1,总课表!I9,"")),"",IF(FIND($E$1,总课表!I9)>0,总课表!I9,"")) | ... U9: =IF(ISERROR(IF(FIND($E$1,总课表!U9)>1,总课表!U9,"")),"",IF(FIND($E$1,总课表!U9)>0,总课表!U9,""))
A10: 19物网2 | B10: =IF(ISERROR(IF(FIND($E$1,总课表!B10)>1,总课表!B10,"")),"",IF(FIND($E$1,总课表!B10)>0,总课表!B10,"")) | C10: =IF(ISERROR(IF(FIND($E$1,总课表!C10)>1,总课表!C10,"")),"",IF(FIND($E$1,总课表!C10)>0,总课表!C10,"")) | D10: =IF(ISERROR(IF(FIND($E$1,总课表!D10)>1,总课表!D10,"")),"",IF(FIND($E$1,总课表!D10)>0,总课表!D10,"")) | E10: =IF(ISERROR(IF(FIND($E$1,总课表!E10)>1,总课表!E10,"")),"",IF(FIND($E$1,总课表!E10)>0,总课表!E10,"")) | F10: =IF(ISERROR(IF(FIND($E$1,总课表!F10)>1,总课表!F10,"")),"",IF(FIND($E$1,总课表!F10)>0,总课表!F10,"")) | G10: =IF(ISERROR(IF(FIND($E$1,总课表!G10)>1,总课表!G10,"")),"",IF(FIND($E$1,总课表!G10)>0,总课表!G10,"")) | H10: =IF(ISERROR(IF(FIND($E$1,总课表!H10)>1,总课表!H10,"")),"",IF(FIND($E$1,总课表!H10)>0,总课表!H10,"")) | I10: =IF(ISERROR(IF(FIND($E$1,总课表!I10)>1,总课表!I10,"")),"",IF(FIND($E$1,总课表!I10)>0,总课表!I10,"")) | ... U10: =IF(ISERROR(IF(FIND($E$1,总课表!U10)>1,总课表!U10,"")),"",IF(FIND($E$1,总课表!U10)>0,总课表!U10,""))
A11: 19物网3 | B11: =IF(ISERROR(IF(FIND($E$1,总课表!B11)>1,总课表!B11,"")),"",IF(FIND($E$1,总课表!B11)>0,总课表!B11,"")) | C11: =IF(ISERROR(IF(FIND($E$1,总课表!C11)>1,总课表!C11,"")),"",IF(FIND($E$1,总课表!C11)>0,总课表!C11,"")) | D11: =IF(ISERROR(IF(FIND($E$1,总课表!D11)>1,总课表!D11,"")),"",IF(FIND($E$1,总课表!D11)>0,总课表!D11,"")) | E11: =IF(ISERROR(IF(FIND($E$1,总课表!E11)>1,总课表!E11,"")),"",IF(FIND($E$1,总课表!E11)>0,总课表!E11,"")) | F11: =IF(ISERROR(IF(FIND($E$1,总课表!F11)>1,总课表!F11,"")),"",IF(FIND($E$1,总课表!F11)>0,总课表!F11,"")) | G11: =IF(ISERROR(IF(FIND($E$1,总课表!G11)>1,总课表!G11,"")),"",IF(FIND($E$1,总课表!G11)>0,总课表!G11,"")) | H11: =IF(ISERROR(IF(FIND($E$1,总课表!H11)>1,总课表!H11,"")),"",IF(FIND($E$1,总课表!H11)>0,总课表!H11,"")) | I11: =IF(ISERROR(IF(FIND($E$1,总课表!I11)>1,总课表!I11,"")),"",IF(FIND($E$1,总课表!I11)>0,总课表!I11,"")) | ... U11: =IF(ISERROR(IF(FIND($E$1,总课表!U11)>1,总课表!U11,"")),"",IF(FIND($E$1,总课表!U11)>0,总课表!U11,""))
A12: 19物网4 | B12: =IF(ISERROR(IF(FIND($E$1,总课表!B12)>1,总课表!B12,"")),"",IF(FIND($E$1,总课表!B12)>0,总课表!B12,"")) | C12: =IF(ISERROR(IF(FIND($E$1,总课表!C12)>1,总课表!C12,"")),"",IF(FIND($E$1,总课表!C12)>0,总课表!C12,"")) | D12: =IF(ISERROR(IF(FIND($E$1,总课表!D12)>1,总课表!D12,"")),"",IF(FIND($E$1,总课表!D12)>0,总课表!D12,"")) | E12: =IF(ISERROR(IF(FIND($E$1,总课表!E12)>1,总课表!E12,"")),"",IF(FIND($E$1,总课表!E12)>0,总课表!E12,"")) | F12: =IF(ISERROR(IF(FIND($E$1,总课表!F12)>1,总课表!F12,"")),"",IF(FIND($E$1,总课表!F12)>0,总课表!F12,"")) | G12: =IF(ISERROR(IF(FIND($E$1,总课表!G12)>1,总课表!G12,"")),"",IF(FIND($E$1,总课表!G12)>0,总课表!G12,"")) | H12: =IF(ISERROR(IF(FIND($E$1,总课表!H12)>1,总课表!H12,"")),"",IF(FIND($E$1,总课表!H12)>0,总课表!H12,"")) | I12: =IF(ISERROR(IF(FIND($E$1,总课表!I12)>1,总课表!I12,"")),"",IF(FIND($E$1,总课表!I12)>0,总课表!I12,"")) | ... U12: =IF(ISERROR(IF(FIND($E$1,总课表!U12)>1,总课表!U12,"")),"",IF(FIND($E$1,总课表!U12)>0,总课表!U12,""))
A13: 19计网1 | B13: =IF(ISERROR(IF(FIND($E$1,总课表!B13)>1,总课表!B13,"")),"",IF(FIND($E$1,总课表!B13)>0,总课表!B13,"")) | C13: =IF(ISERROR(IF(FIND($E$1,总课表!C13)>1,总课表!C13,"")),"",IF(FIND($E$1,总课表!C13)>0,总课表!C13,"")) | D13: =IF(ISERROR(IF(FIND($E$1,总课表!D13)>1,总课表!D13,"")),"",IF(FIND($E$1,总课表!D13)>0,总课表!D13,"")) | E13: =IF(ISERROR(IF(FIND($E$1,总课表!E13)>1,总课表!E13,"")),"",IF(FIND($E$1,总课表!E13)>0,总课表!E13,"")) | F13: =IF(ISERROR(IF(FIND($E$1,总课表!F13)>1,总课表!F13,"")),"",IF(FIND($E$1,总课表!F13)>0,总课表!F13,"")) | G13: =IF(ISERROR(IF(FIND($E$1,总课表!G13)>1,总课表!G13,"")),"",IF(FIND($E$1,总课表!G13)>0,总课表!G13,"")) | H13: =IF(ISERROR(IF(FIND($E$1,总课表!H13)>1,总课表!H13,"")),"",IF(FIND($E$1,总课表!H13)>0,总课表!H13,"")) | I13: =IF(ISERROR(IF(FIND($E$1,总课表!I13)>1,总课表!I13,"")),"",IF(FIND($E$1,总课表!I13)>0,总课表!I13,"")) | ... U13: =IF(ISERROR(IF(FIND($E$1,总课表!U13)>1,总课表!U13,"")),"",IF(FIND($E$1,总课表!U13)>0,总课表!U13,""))
A14: 19计网2 | B14: =IF(ISERROR(IF(FIND($E$1,总课表!B14)>1,总课表!B14,"")),"",IF(FIND($E$1,总课表!B14)>0,总课表!B14,"")) | C14: =IF(ISERROR(IF(FIND($E$1,总课表!C14)>1,总课表!C14,"")),"",IF(FIND($E$1,总课表!C14)>0,总课表!C14,"")) | D14: =IF(ISERROR(IF(FIND($E$1,总课表!D14)>1,总课表!D14,"")),"",IF(FIND($E$1,总课表!D14)>0,总课表!D14,"")) | E14: =IF(ISERROR(IF(FIND($E$1,总课表!E14)>1,总课表!E14,"")),"",IF(FIND($E$1,总课表!E14)>0,总课表!E14,"")) | F14: =IF(ISERROR(IF(FIND($E$1,总课表!F14)>1,总课表!F14,"")),"",IF(FIND($E$1,总课表!F14)>0,总课表!F14,"")) | G14: =IF(ISERROR(IF(FIND($E$1,总课表!G14)>1,总课表!G14,"")),"",IF(FIND($E$1,总课表!G14)>0,总课表!G14,"")) | H14: =IF(ISERROR(IF(FIND($E$1,总课表!H14)>1,总课表!H14,"")),"",IF(FIND($E$1,总课表!H14)>0,总课表!H14,"")) | I14: =IF(ISERROR(IF(FIND($E$1,总课表!I14)>1,总课表!I14,"")),"",IF(FIND($E$1,总课表!I14)>0,总课表!I14,"")) | ... U14: =IF(ISERROR(IF(FIND($E$1,总课表!U14)>1,总课表!U14,"")),"",IF(FIND($E$1,总课表!U14)>0,总课表!U14,""))
... A29: 20机器人 | B29: =IF(ISERROR(IF(FIND($E$1,总课表!B29)>1,总课表!B29,"")),"",IF(FIND($E$1,总课表!B29)>0,总课表!B29,"")) | C29: =IF(ISERROR(IF(FIND($E$1,总课表!C29)>1,总课表!C29,"")),"",IF(FIND($E$1,总课表!C29)>0,总课表!C29,"")) | D29: =IF(ISERROR(IF(FIND($E$1,总课表!D29)>1,总课表!D29,"")),"",IF(FIND($E$1,总课表!D29)>0,总课表!D29,"")) | E29: =IF(ISERROR(IF(FIND($E$1,总课表!E29)>1,总课表!E29,"")),"",IF(FIND($E$1,总课表!E29)>0,总课表!E29,"")) | F29: =IF(ISERROR(IF(FIND($E$1,总课表!F29)>1,总课表!F29,"")),"",IF(FIND($E$1,总课表!F29)>0,总课表!F29,"")) | G29: =IF(ISERROR(IF(FIND($E$1,总课表!G29)>1,总课表!G29,"")),"",IF(FIND($E$1,总课表!G29)>0,总课表!G29,"")) | H29: =IF(ISERROR(IF(FIND($E$1,总课表!H29)>1,总课表!H29,"")),"",IF(FIND($E$1,总课表!H29)>0,总课表!H29,"")) | I29: =IF(ISERROR(IF(FIND($E$1,总课表!I29)>1,总课表!I29,"")),"",IF(FIND($E$1,总课表!I29)>0,总课表!I29,"")) | ... U29: =IF(ISERROR(IF(FIND($E$1,总课表!U29)>1,总课表!U29,"")),"",IF(FIND($E$1,总课表!U29)>0,总课表!U29,""))

Sheet 教师姓名
A2: 张磊
A3: 柳金堤
A4: 宋剑文
A5: 吴俊杰
A6: 曾婧玉
A7: 朱朋
A8: 刘明良
A9: 王丽
A10: 游思明
A11: 周香萍
A12: 徐艳
A13: 刘敏
... A32: 王建立
A33: 邹浩桢 | B33: 徐博程
A34: 李俊杰 | B34: 屈美玲
A35: 陈良 | B35: 胡晨雨
A36: 王昌原
A37: 耿锐
A38: 赵艳云
A39: 袁超
A40: 徐春华
A41: 徐行
A42: 肖继林
A43: 何丹
A44: 黎海春
A45: 文林一村
A46: 机房

Sheet 周历
A1: 2020-2021学年第二学期周历（下埠教学点）
A2: 班级名称 | B2: 课程名称 | C2: 类别 | D2: 周学时/周次 | E2: 1 | F2: 2 | G2: 3 | H2: 4 | I2: 5 | J2: 6 | K2: 7 | L2: 8 | M2: 9 | N2: 10 | O2: 11 | P2: 12 | Q2: 13 | R2: 14 | S2: 15 | T2: 16 | U2: 17 | V2: 18 | W2: 考核方式 | X2: 教师
A3: 18计算机应用技术1班 | B3: Java项目综合案例开发 | C3: 课程 | D3: 6 | G3: 创业培训周 | K3: 毕业设计及答辨 | W3: 考查 | X3: 王昌原
B4: Web项目综合案例开发 | C4: 课程 | D4: 6 | W4: 考试 | X4: 耿锐
B5: 就业指导 | C5: 课程 | D5: 2 | W5: 考查 | X5: 赵艳云
B6: 软件工程 | C6: 课程 | D6: 2 | W6: 考查 | X6: 李星
B7: 形势与政策5 | C7: 课程 | D7: 2 | W7: 考查
B8: 毕业设计及答辨 | C8: 环节 | D8: 1 | W8: 考查
A9: 18计算机应用技术2班 | B9: Java项目综合案例开发 | C9: 课程 | D9: 6 | G9: 创业培训周 | K9: 毕业设计及答辨 | W9: 考查 | X9: 王昌原
B10: Web项目综合案例开发 | C10: 课程 | D10: 6 | W10: 考试 | X10: 耿锐
B11: 就业指导 | C11: 课程 | D11: 2 | W11: 考查 | X11: 赵艳云
B12: 软件工程 | C12: 课程 | D12: 2 | W12: 考查 | X12: 李星
B13: 形势与政策5 | C13: 课程 | D13: 2 | W13: 考查
B14: 毕业设计及答辨 | C14: 环节 | D14: 1 | W14: 考查
A15: 18计算机应用技术3班 | B15: Java项目综合案例开发 | C15: 课程 | D15: 6 | J15: 创业培训周 | K15: 毕业设计及答辨 | W15: 考查 | X15: 王昌原
B16: Web项目综合案例开发 | C16: 课程 | D16: 6 | W16: 考试 | X16: 耿锐
B17: 就业指导 | C17: 课程 | D17: 2 | W17: 考查 | X17: 赵艳云
B18: 软件工程 | C18: 课程 | D18: 2 | W18: 考查 | X18: 李星
B19: 形势与政策5 | C19: 课程 | D19: 2 | W19: 考查
B20: 毕业设计及答辨 | C20: 环节 | D20: 1 | W20: 考查
A21: 18计算机应用技术4班 | B21: Java项目综合案例开发 | C21: 课程 | D21: 6 | J21: 创业培训周 | K21: 毕业设计及答辨 | W21: 考查 | X21: 王昌原
B22: Web项目综合案例开发 | C22: 课程 | D22: 6 | W22: 考试 | X22: 耿锐
B23: 就业指导 | C23: 课程 | D23: 2 | W23: 考查 | X23: 赵艳云
B24: 软件工程 | C24: 课程 | D24: 2 | W24: 考查 | X24: 李星
B25: 形势与政策5 | C25: 课程 | D25: 2 | W25: 考查
B26: 毕业设计及答辨 | C26: 环节 | D26: 1 | W26: 考查
A27: 18市场营销1班 | B27: 零售业营销 | C27: 课程 | D27: 6 | K27: 创业培训周 | L27: 毕业设计及答辩 | W27: 考试 | X27: 徐艳
B28: 新媒体营销 | C28: 课程 | D28: 6 | W28: 考试 | X28: 袁超
B29: 交际与口才 | C29: 课程 | D29: 4 | W29: 考查 | X29: 钟丽娜
B30: 办公软件高级应用 | C30: 课程 | D30: 6 | W30: 考查 | X30: 唐晗
B31: 形势与政策5 | C31: 课程 | D31: 2 | W31: 考查
B32: 就业指导 | C32: 课程 | D32: 2 | W32: 考查 | X32: 赵艳云
B33: 毕业设计及答辩 | C33: 环节 | W33: 考查
A34: 18市场营销2班 | B34: 零售业营销 | C34: 课程 | D34: 6 | K34: 创业培训周 | L34: 毕业设计及答辩 | W34: 考试 | X34: 徐艳
B35: 新媒体营销 | C35: 课程 | D35: 6 | W35: 考试 | X35: 袁超
B36: 交际与口才 | C36: 课程 | D36: 4 | W36: 考查 | X36: 钟丽娜
B37: 办公软件高级应用 | C37: 课程 | D37: 6 | W37: 考查 | X37: 袁军萍
B38: 形势与政策5 | C38: 课程 | D38: 2 | W38: 考查
B39: 就业指导 | C39: 课程 | D39: 2 | W39: 考查 | X39: 赵艳云
B40: 毕业设计及答辩 | C40: 环节 | W40: 考查
...

Sheet Sheet1
A1: 2 | B1: =RIGHT(总课表!I3,6) -> 耿锐 报告厅 | G1: =LEFT(总课表!I3,3) -> 耿锐 | H1: =LEFT(总课表!I3,3) -> 耿锐 | I1: =LEFT(总课表!M3,3) -> 耿锐 | J1: =LEFT(总课表!Q3,3) -> 赵艳云
A2: 4 | B2: =RIGHT(总课表!I4,6) -> 耿锐 报告厅 | G2: =LEFT(总课表!E4,3) -> 耿锐 | H2: =LEFT(总课表!I4,3) -> 耿锐 | I2: =LEFT(总课表!M4,3) -> 耿锐 | J2: =LEFT(总课表!Q4,3) -> 赵艳云
A3: 6 | B3: =RIGHT(总课表!I5,6) -> 耿锐 报告厅 | G3: =LEFT(总课表!E5,3) -> 耿锐 | H3: =LEFT(总课表!I5,3) -> 耿锐 | I3: =LEFT(总课表!M5,3) -> 耿锐 | J3: =LEFT(总课表!Q5,3) -> 赵艳云
A4: 11 | B4: =RIGHT(总课表!I6,6) -> 耿锐 报告厅 | G4: =LEFT(总课表!E6,3) -> 耿锐 | H4: =LEFT(总课表!I6,3) -> 耿锐 | I4: =LEFT(总课表!M6,3) -> 耿锐 | J4: =LEFT(总课表!Q6,3) -> 赵艳云
A5: 24 | B5: =RIGHT(总课表!I16,6) -> 践行楼101 | G5: =LEFT(总课表!E7,3) -> 袁军萍 | H5: =LEFT(总课表!I7,3) -> 袁军萍 | I5: =LEFT(总课表!M7,3) -> 赵艳云 | J5: =LEFT(总课表!Q7,3) -> 袁超
A6: 17 | B6: =RIGHT(总课表!I11,6) -> 践行楼103 | G6: =LEFT(总课表!E8,3) -> 袁军萍 | H6: =LEFT(总课表!I8,3) -> 袁军萍 | I6: =LEFT(总课表!M8,3) -> 赵艳云 | J6: =LEFT(总课表!Q8,3) -> 袁超
A7: 16 | B7: =RIGHT(总课表!I12,6) -> 践行楼104 | G7: =LEFT(总课表!E9,3) -> 李星 | H7: =LEFT(总课表!I9,3) -> 钟丽娜 | I7: =LEFT(总课表!M9,3) -> 徐行 | J7: =LEFT(总课表!Q9,3) -> 徐行
A8: 12 | B8: =RIGHT(总课表!I20,6) -> 践行楼201 | G8: =LEFT(总课表!E10,3) -> 张磊 | H8: =LEFT(总课表!I10,3) -> 钟丽娜 | I8: =LEFT(总课表!M10,3) -> 徐行 | J8: =LEFT(总课表!Q10,3) -> 钟丽娜
A9: 8 | B9: =RIGHT(总课表!I21,6) -> 践行楼201 | I9: =LEFT(总课表!M11,3) -> 张磊
A10: 22 | B10: =RIGHT(总课表!I14,6) -> 践行楼202 | G10: =LEFT(总课表!E12,3) -> 徐春华 | H10: =LEFT(总课表!I12,3) -> 何丹 | J10: =LEFT(总课表!Q12,3) -> 何丹
A11: 9 | B11: =RIGHT(总课表!I15,6) -> 践行楼203 | H11: =LEFT(总课表!I13,3) -> 黎海春 | I11: =LEFT(总课表!M13,3) -> 徐春华 | J11: =LEFT(总课表!Q13,3) -> 李星
A12: 23 | B12: =RIGHT(总课表!I9,6) -> 践行楼204 | G12: =LEFT(总课表!E14,3) -> 黎海春 | H12: =LEFT(总课表!I14,3) -> 徐春华 | I12: =LEFT(总课表!M14,3) -> 李星
A13: 21 | B13: =RIGHT(总课表!I10,6) -> 践行楼204 | G13: =LEFT(总课表!E15,3) -> 徐行
A14: 3 | B14: =RIGHT(总课表!I7,6) -> 践行楼401 | G14: =LEFT(总课表!E16,3) -> 袁超 | H14: =LEFT(总课表!I16,3) -> 袁超 | J14: =LEFT(总课表!Q16,3) -> 营销型
A15: 5 | B15: =RIGHT(总课表!I8,6) -> 践行楼401 | G15: =LEFT(总课表!E17,3) -> 彭润华 | H15: =LEFT(总课表!I17,3) -> 唐晗 | I15: =LEFT(总课表!M17,3) -> 王丽 | J15: =LEFT(总课表!Q17,3) -> 贺春
A16: 18 | B16: =RIGHT(总课表!I22,6) -> 践行楼403 | G16: =LEFT(总课表!E18,3) -> 彭润华 | H16: =LEFT(总课表!I18,3) -> 贺春 | I16: =LEFT(总课表!M18,3) -> 胡玲 | J16: =LEFT(总课表!Q18,3) -> 贺春
A17: 26 | B17: =RIGHT(总课表!I23,6) -> 践行楼403 | G17: =LEFT(总课表!E19,3) -> 陈娟 | H17: =LEFT(总课表!I19,3) -> 胡玲 | I17: =LEFT(总课表!M19,3) -> 唐晗 | J17: =LEFT(总课表!Q19,3) -> 胡玲
A18: 7 | B18: =RIGHT(总课表!I25,6) -> 映荷楼101 | G18: =LEFT(总课表!E20,3) -> 吴友才 | H18: =LEFT(总课表!I20,3) -> 周香萍 | I18: =LEFT(总课表!M20,3) -> 袁军萍 | J18: =LEFT(总课表!Q20,3) -> 李含笑
A19: 19 | B19: =RIGHT(总课表!I17,6) -> 映荷楼103 | G19: =LEFT(总课表!E21,3) -> 周香萍 | H19: =LEFT(总课表!I21,3) -> 周香萍 | I19: =LEFT(总课表!M21,3) -> 李含笑 | J19: =LEFT(总课表!Q21,3) -> 谢鹏
A20: 1 | B20: =RIGHT(总课表!I27,6) -> 映荷楼104 | G20: =LEFT(总课表!E22,3) -> 柳航 | H20: =LEFT(总课表!I22,3) -> 柳航 | I20: =LEFT(总课表!M22,3) -> 贺春 | J20: =LEFT(总课表!Q22,3) -> 谢嘉祺
A21: 20 | B21: =RIGHT(总课表!I19,6) -> 映荷楼201 | G21: =LEFT(总课表!E23,3) -> 唐晗 | H21: =LEFT(总课表!I23,3) -> 柳航 | I21: =LEFT(总课表!M23,3) -> 谢嘉祺 | J21: =LEFT(总课表!Q23,3) -> 肖继林
A22: 27 | B22: =RIGHT(总课表!I18,6) -> 映荷楼202 | G22: =LEFT(总课表!E24,3) -> 谢鹏 | H22: =LEFT(总课表!I24,3) -> 李含笑 | I22: =LEFT(总课表!M24,3) -> 吴友才 | J22: =LEFT(总课表!Q24,3) -> 张磊
A23: 15 | B23: =RIGHT(总课表!I26,6) -> 映荷楼204 | G23: =LEFT(总课表!E25,3) -> 文林一 | H23: =LEFT(总课表!I25,3) -> 陈娟 | I23: =LEFT(总课表!M25,3) -> 彭明 | J23: =LEFT(总课表!Q25,3) -> 文林一
A24: 13 | B24: =RIGHT(总课表!I24,6) -> 映荷楼301 | G24: =LEFT(总课表!E26,3) -> 彭明 | H24: =LEFT(总课表!I26,3) -> 黄仕尘 | I24: =LEFT(总课表!M26,3) -> 彭润华 | J24: =LEFT(总课表!Q26,3) -> 罗夏芸
A25: 14 | B25: =RIGHT(总课表!I13,6) -> 映荷楼302 | G25: =LEFT(总课表!E27,3) -> 黄仕尘 | H25: =LEFT(总课表!I27,3) -> 彭润华 | I25: =LEFT(总课表!M27,3) -> 周香萍 | J25: =LEFT(总课表!Q27,3) -> 王丽
A26: 10 | B26: =RIGHT(总课表!I28,6) -> 映荷楼402 | G26: =LEFT(总课表!E28,3) -> 钟子良 | H26: =LEFT(总课表!I28,3) -> 罗夏芸 | I26: =LEFT(总课表!M28,3) -> 罗夏芸 | J26: =LEFT(总课表!Q28,3) -> 周香萍
A27: 25 | B27: =RIGHT(总课表!I29,6) -> 映荷楼403 | G27: =LEFT(总课表!E29,3) -> 钟子良 | H27: =LEFT(总课表!I29,3) -> 罗夏芸 | I27: =LEFT(总课表!M29,3) -> 罗夏芸 | J27: =LEFT(总课表!Q29,3) -> 钟子良
N29: 班级 | O29: 劳动周
N30: 20机电 | O30: 2
N31: 20建工 | O31: 3
N32: 20工造 | O32: 4
N33: 20机器人 | O33: 5
N34: 20电商2 | O34: 6
N35: 20电商1 | O35: 7
N36: 20计应2 | O36: 8
N37: 20幼教2 | O37: 10
N38: 20计应1 | O38: 11
N39: 20会计 | O39: 12
N40: 20幼教1 | O40: 13
N41: 20幼教3 | O41: 14
...
